Workbook

Sheet Eingabedaten
B1: Eigene Daten in weiße Felder einfügen
B3: Vorname: | C3: Michael
B4: Nachname: | C4: Sternicki
B5: Jahr: | C5: 2025
B7: Praktikumsbetrieb: | C7: Echoscout GmbH
B8: Straße: | C8: Maria-Goeppert-Str. 3
B9: PLZ: | C9: 23562
B10: Ort: | C10: Lübeck
B13: Bild Header einfügen
B14: #VALUE!
B17: Bild Teilnehmerunterschrift einfügen:
B18: #VALUE!
B21: Bild AusbilderIn Unterschrift einfügen

Sheet KOPIERVORLAGE
B2: Praktikumsbetrieb
B3: Echoscout GmbH | F3: =Eingabedaten!B14 -> #VALUE!
B4: Maria-Goeppert-Str. 3
B5: 23562 Lübeck
B7: Stundennachweis
F8: Name, Vorname
F9: =Eingabedaten!C4 & ", " & Eingabedaten!C3 -> Sternicki, Michael
B13: Tag | C13: Datum | D13: Arbeitszeit von -bis | F13: Pause in min. | G13: Std. gesamt | H13: Bemerkung
B14: =TEXT(C14,"TTT") -> Sa | C14: =B9 -> 0 | D14: =IF(OR(B14="Sa",B14="So"), "", TIME(8,30,0)) | E14: =IF(OR(B14="Sa",B14="So"), "", TIME(17,0,0)) | F14: =IF(OR(B14="Sa",B14="So"), "", 30) | G14: =IF(B14="Sa",SUM(G9:G13),IF(B14="So","",(E14-D14)*24-F14/60)) -> 0 | H14: /
B15: =TEXT(C15,"TTT") -> So | C15: =C14+1 -> 1 | D15: =IF(OR(B15="Sa",B15="So"), "", TIME(8,30,0)) | E15: =IF(OR(B15="Sa",B15="So"), "", TIME(17,0,0)) | F15: =IF(OR(B15="Sa",B15="So"), "", 30) | G15: =IF(B15="Sa",SUM(G10:G14),IF(B15="So","",(E15-D15)*24-F15/60)) | H15: /
B16: =TEXT(C16,"TTT") -> Mo | C16: =C15+1 -> 2 | D16: =IF(OR(B16="Sa",B16="So"), "", TIME(8,30,0)) -> 0.35416667 | E16: =IF(OR(B16="Sa",B16="So"), "", TIME(17,0,0)) -> 0.70833333 | F16: =IF(OR(B16="Sa",B16="So"), "", 30) -> 30 | G16: =IF(B16="Sa",SUM(G11:G15),IF(B16="So","",(E16-D16)*24-F16/60)) -> 8 | H16: /
B17: =TEXT(C17,"TTT") -> Di | C17: =C16+1 -> 3 | D17: =IF(OR(B17="Sa",B17="So"), "", TIME(8,30,0)) -> 0.35416667 | E17: =IF(OR(B17="Sa",B17="So"), "", TIME(17,0,0)) -> 0.70833333 | F17: =IF(OR(B17="Sa",B17="So"), "", 30) -> 30 | G17: =IF(B17="Sa",SUM(G12:G16),IF(B17="So","",(E17-D17)*24-F17/60)) -> 8 | H17: /
B18: =TEXT(C18,"TTT") -> Mi | C18: =C17+1 -> 4 | D18: =IF(OR(B18="Sa",B18="So"), "", TIME(8,30,0)) -> 0.35416667 | E18: =IF(OR(B18="Sa",B18="So"), "", TIME(17,0,0)) -> 0.70833333 | F18: =IF(OR(B18="Sa",B18="So"), "", 30) -> 30 | G18: =IF(B18="Sa",SUM(G13:G17),IF(B18="So","",(E18-D18)*24-F18/60)) -> 8 | H18: /
B19: =TEXT(C19,"TTT") -> Do | C19: =C18+1 -> 5 | D19: =IF(OR(B19="Sa",B19="So"), "", TIME(8,30,0)) -> 0.35416667 | E19: =IF(OR(B19="Sa",B19="So"), "", TIME(17,0,0)) -> 0.70833333 | F19: =IF(OR(B19="Sa",B19="So"), "", 30) -> 30 | G19: =IF(B19="Sa",SUM(G14:G18),IF(B19="So","",(E19-D19)*24-F19/60)) -> 8 | H19: /
B20: =TEXT(C20,"TTT") -> Fr | C20: =C19+1 -> 6 | D20: =IF(OR(B20="Sa",B20="So"), "", TIME(8,30,0)) -> 0.35416667 | E20: =IF(OR(B20="Sa",B20="So"), "", TIME(17,0,0)) -> 0.70833333 | F20: =IF(OR(B20="Sa",B20="So"), "", 30) -> 30 | G20: =IF(B20="Sa",SUM(G15:G19),IF(B20="So","",(E20-D20)*24-F20/60)) -> 8 | H20: /
B21: =TEXT(C21,"TTT") -> Sa | C21: =C20+1 -> 7 | D21: =IF(OR(B21="Sa",B21="So"), "", TIME(8,30,0)) | E21: =IF(OR(B21="Sa",B21="So"), "", TIME(17,0,0)) | F21: =IF(OR(B21="Sa",B21="So"), "", 30) | G21: =IF(B21="Sa",SUM(G16:G20),IF(B21="So","",(E21-D21)*24-F21/60)) -> 40 | H21: /
B22: =TEXT(C22,"TTT") -> So | C22: =C21+1 -> 8 | D22: =IF(OR(B22="Sa",B22="So"), "", TIME(8,30,0)) | E22: =IF(OR(B22="Sa",B22="So"), "", TIME(17,0,0)) | F22: =IF(OR(B22="Sa",B22="So"), "", 30) | G22: =IF(B22="Sa",SUM(G17:G21),IF(B22="So","",(E22-D22)*24-F22/60)) | H22: /
B23: =TEXT(C23,"TTT") -> Mo | C23: =C22+1 -> 9 | D23: =IF(OR(B23="Sa",B23="So"), "", TIME(8,30,0)) -> 0.35416667 | E23: =IF(OR(B23="Sa",B23="So"), "", TIME(17,0,0)) -> 0.70833333 | F23: =IF(OR(B23="Sa",B23="So"), "", 30) -> 30 | G23: =IF(B23="Sa",SUM(G18:G22),IF(B23="So","",(E23-D23)*24-F23/60)) -> 8 | H23: /
B24: =TEXT(C24,"TTT") -> Di | C24: =C23+1 -> 10 | D24: =IF(OR(B24="Sa",B24="So"), "", TIME(8,30,0)) -> 0.35416667 | E24: =IF(OR(B24="Sa",B24="So"), "", TIME(17,0,0)) -> 0.70833333 | F24: =IF(OR(B24="Sa",B24="So"), "", 30) -> 30 | G24: =IF(B24="Sa",SUM(G19:G23),IF(B24="So","",(E24-D24)*24-F24/60)) -> 8 | H24: /
B25: =TEXT(C25,"TTT") -> Mi | C25: =C24+1 -> 11 | D25: =IF(OR(B25="Sa",B25="So"), "", TIME(8,30,0)) -> 0.35416667 | E25: =IF(OR(B25="Sa",B25="So"), "", TIME(17,0,0)) -> 0.70833333 | F25: =IF(OR(B25="Sa",B25="So"), "", 30) -> 30 | G25: =IF(B25="Sa",SUM(G20:G24),IF(B25="So","",(E25-D25)*24-F25/60)) -> 8 | H25: /
B26: =TEXT(C26,"TTT") -> Do | C26: =C25+1 -> 12 | D26: =IF(OR(B26="Sa",B26="So"), "", TIME(8,30,0)) -> 0.35416667 | E26: =IF(OR(B26="Sa",B26="So"), "", TIME(17,0,0)) -> 0.70833333 | F26: =IF(OR(B26="Sa",B26="So"), "", 30) -> 30 | G26: =IF(B26="Sa",SUM(G21:G25),IF(B26="So","",(E26-D26)*24-F26/60)) -> 8 | H26: /
... B44: =TEXT(C44,"TTT") -> Mo | C44: =C43+1 -> 30 | D44: =IF(OR(B44="Sa",B44="So"), "", TIME(8,30,0)) -> 0.35416667 | E44: =IF(OR(B44="Sa",B44="So"), "", TIME(17,0,0)) -> 0.70833333 | F44: =IF(OR(B44="Sa",B44="So"), "", 30) -> 30 | G44: =IF(B44="Sa",SUM(G39:G43),IF(B44="So","",(E44-D44)*24-F44/60)) -> 8 | H44: /
B45: =TEXT(C45,"TTT") -> Di | C45: =C44+1 -> 31 | D45: =IF(OR(B45="Sa",B45="So"), "", TIME(8,30,0)) -> 0.35416667 | E45: =IF(OR(B45="Sa",B45="So"), "", TIME(17,0,0)) -> 0.70833333 | F45: =IF(OR(B45="Sa",B45="So"), "", 30) -> 30 | G45: =IF(B45="Sa",SUM(G40:G44),IF(B45="So","",(E45-D45)*24-F45/60)) -> 8
B47: =Eingabedaten!B18 -> #VALUE!
F48: =Eingabedaten!B22 -> 0
B50: =C44 -> 30 | F50: =B50 -> 30
B51: Datum, Unterschrift Teilnehmer | F51: Datum, Stempel, Unterschrift Betrieb

Sheet Oktober
B2: Praktikumsbetrieb
B3: Echoscout GmbH | F3: =Eingabedaten!B14 -> #VALUE!
B4: Maria-Goeppert-Str. 3
B5: 23562 Lübeck
B7: Stundennachweis
F8: Name, Vorname
B9: 45931 | F9: =Eingabedaten!C4 & ", " & Eingabedaten!C3 -> Sternicki, Michael
B13: Tag | C13: Datum | D13: Arbeitszeit von -bis | F13: Pause in min. | G13: Std. gesamt | H13: Bemerkung
B14: =TEXT(C14,"TTT") -> Mi | C14: =B9 -> 45931 | D14: =IF(OR(B14="Sa",B14="So"), "", TIME(8,30,0)) -> 0.35416667 | E14: =IF(OR(B14="Sa",B14="So"), "", TIME(17,0,0)) -> 0.70833333 | F14: =IF(OR(B14="Sa",B14="So"), "", 30) -> 30 | G14: =IF(B14="Sa",SUM(G9:G13),IF(B14="So","",(E14-D14)*24-F14/60)) -> 8 | H14: /
B15: =TEXT(C15,"TTT") -> Do | C15: =C14+1 -> 45932 | D15: =IF(OR(B15="Sa",B15="So"), "", TIME(8,30,0)) -> 0.35416667 | E15: =IF(OR(B15="Sa",B15="So"), "", TIME(17,0,0)) -> 0.70833333 | F15: =IF(OR(B15="Sa",B15="So"), "", 30) -> 30 | G15: =IF(B15="Sa",SUM(G10:G14),IF(B15="So","",(E15-D15)*24-F15/60)) -> 8 | H15: /
B16: =TEXT(C16,"TTT") -> Fr | C16: =C15+1 -> 45933 | D16: =IF(OR(B16="Sa",B16="So"), "", TIME(8,30,0)) -> 0.35416667 | E16: =IF(OR(B16="Sa",B16="So"), "", TIME(17,0,0)) -> 0.70833333 | F16: =IF(OR(B16="Sa",B16="So"), "", 30) -> 30 | G16: =IF(B16="Sa",SUM(G11:G15),IF(B16="So","",(E16-D16)*24-F16/60)) -> 8 | H16: /
B17: =TEXT(C17,"TTT") -> Sa | C17: =C16+1 -> 45934 | D17: =IF(OR(B17="Sa",B17="So"), "", TIME(8,30,0)) | E17: =IF(OR(B17="Sa",B17="So"), "", TIME(17,0,0)) | F17: =IF(OR(B17="Sa",B17="So"), "", 30) | G17: =IF(B17="Sa",SUM(G12:G16),IF(B17="So","",(E17-D17)*24-F17/60)) -> 24 | H17: /
B18: =TEXT(C18,"TTT") -> So | C18: =C17+1 -> 45935 | D18: =IF(OR(B18="Sa",B18="So"), "", TIME(8,30,0)) | E18: =IF(OR(B18="Sa",B18="So"), "", TIME(17,0,0)) | F18: =IF(OR(B18="Sa",B18="So"), "", 30) | G18: =IF(B18="Sa",SUM(G13:G17),IF(B18="So","",(E18-D18)*24-F18/60)) | H18: /
B19: =TEXT(C19,"TTT") -> Mo | C19: =C18+1 -> 45936 | D19: =IF(OR(B19="Sa",B19="So"), "", TIME(8,30,0)) -> 0.35416667 | E19: =IF(OR(B19="Sa",B19="So"), "", TIME(17,0,0)) -> 0.70833333 | F19: =IF(OR(B19="Sa",B19="So"), "", 30) -> 30 | G19: =IF(B19="Sa",SUM(G14:G18),IF(B19="So","",(E19-D19)*24-F19/60)) -> 8 | H19: /
B20: =TEXT(C20,"TTT") -> Di | C20: =C19+1 -> 45937 | D20: =IF(OR(B20="Sa",B20="So"), "", TIME(8,30,0)) -> 0.35416667 | E20: =IF(OR(B20="Sa",B20="So"), "", TIME(17,0,0)) -> 0.70833333 | F20: =IF(OR(B20="Sa",B20="So"), "", 30) -> 30 | G20: =IF(B20="Sa",SUM(G15:G19),IF(B20="So","",(E20-D20)*24-F20/60)) -> 8 | H20: /
B21: =TEXT(C21,"TTT") -> Mi | C21: =C20+1 -> 45938 | D21: =IF(OR(B21="Sa",B21="So"), "", TIME(8,30,0)) -> 0.35416667 | E21: =IF(OR(B21="Sa",B21="So"), "", TIME(17,0,0)) -> 0.70833333 | F21: =IF(OR(B21="Sa",B21="So"), "", 30) -> 30 | G21: =IF(B21="Sa",SUM(G16:G20),IF(B21="So","",(E21-D21)*24-F21/60)) -> 8 | H21: /
B22: =TEXT(C22,"TTT") -> Do | C22: =C21+1 -> 45939 | D22: =IF(OR(B22="Sa",B22="So"), "", TIME(8,30,0)) -> 0.35416667 | E22: =IF(OR(B22="Sa",B22="So"), "", TIME(17,0,0)) -> 0.70833333 | F22: =IF(OR(B22="Sa",B22="So"), "", 30) -> 30 | G22: =IF(B22="Sa",SUM(G17:G21),IF(B22="So","",(E22-D22)*24-F22/60)) -> 8 | H22: /
B23: =TEXT(C23,"TTT") -> Fr | C23: =C22+1 -> 45940 | D23: =IF(OR(B23="Sa",B23="So"), "", TIME(8,30,0)) -> 0.35416667 | E23: =IF(OR(B23="Sa",B23="So"), "", TIME(17,0,0)) -> 0.70833333 | F23: =IF(OR(B23="Sa",B23="So"), "", 30) -> 30 | G23: =IF(B23="Sa",SUM(G18:G22),IF(B23="So","",(E23-D23)*24-F23/60)) -> 8 | H23: /
B24: =TEXT(C24,"TTT") -> Sa | C24: =C23+1 -> 45941 | D24: =IF(OR(B24="Sa",B24="So"), "", TIME(8,30,0)) | E24: =IF(OR(B24="Sa",B24="So"), "", TIME(17,0,0)) | F24: =IF(OR(B24="Sa",B24="So"), "", 30) | G24: =IF(B24="Sa",SUM(G19:G23),IF(B24="So","",(E24-D24)*24-F24/60)) -> 40 | H24: /
B25: =TEXT(C25,"TTT") -> So | C25: =C24+1 -> 45942 | D25: =IF(OR(B25="Sa",B25="So"), "", TIME(8,30,0)) | E25: =IF(OR(B25="Sa",B25="So"), "", TIME(17,0,0)) | F25: =IF(OR(B25="Sa",B25="So"), "", 30) | G25: =IF(B25="Sa",SUM(G20:G24),IF(B25="So","",(E25-D25)*24-F25/60)) | H25: /
B26: =TEXT(C26,"TTT") -> Mo | C26: =C25+1 -> 45943 | G26: =IF(B26="Sa",SUM(G21:G25),IF(B26="So","",(E26-D26)*24-F26/60)) -> 0 | H26: Keine Praktikumzeit
B27: =TEXT(C27,"TTT") -> Di | C27: =C26+1 -> 45944 | G27: =IF(B27="Sa",SUM(G22:G26),IF(B27="So","",(E27-D27)*24-F27/60)) -> 0 | H27: =H26 -> Keine Praktikumzeit
B28: =TEXT(C28,"TTT") -> Mi | C28: =C27+1 -> 45945 | G28: =IF(B28="Sa",SUM(G23:G27),IF(B28="So","",(E28-D28)*24-F28/60)) -> 0 | H28: Keine Praktikumzeit
B29: =TEXT(C29,"TTT") -> Do | C29: =C28+1 -> 45946 | G29: =IF(B29="Sa",SUM(G24:G28),IF(B29="So","",(E29-D29)*24-F29/60)) -> 0 | H29: =H28 -> Keine Praktikumzeit
B30: =TEXT(C30,"TTT") -> Fr | C30: =C29+1 -> 45947 | G30: =IF(B30="Sa",SUM(G25:G29),IF(B30="So","",(E30-D30)*24-F30/60)) -> 0 | H30: Keine Praktikumzeit
B31: =TEXT(C31,"TTT") -> Sa | C31: =C30+1 -> 45948 | D31: =IF(OR(B31="Sa",B31="So"), "", TIME(8,30,0)) | E31: =IF(OR(B31="Sa",B31="So"), "", TIME(17,0,0)) | F31: =IF(OR(B31="Sa",B31="So"), "", 30) | G31: =IF(B31="Sa",SUM(G26:G30),IF(B31="So","",(E31-D31)*24-F31/60)) -> 0
B32: =TEXT(C32,"TTT") -> So | C32: =C31+1 -> 45949 | D32: =IF(OR(B32="Sa",B32="So"), "", TIME(8,30,0)) | E32: =IF(OR(B32="Sa",B32="So"), "", TIME(17,0,0)) | F32: =IF(OR(B32="Sa",B32="So"), "", 30) | G32: =IF(B32="Sa",SUM(G27:G31),IF(B32="So","",(E32-D32)*24-F32/60)) | H32: /
B33: =TEXT(C33,"TTT") -> Mo | C33: =C32+1 -> 45950 | D33: =IF(OR(B33="Sa",B33="So"), "", TIME(8,30,0)) -> 0.35416667 | E33: =IF(OR(B33="Sa",B33="So"), "", TIME(17,0,0)) -> 0.70833333 | F33: =IF(OR(B33="Sa",B33="So"), "", 30) -> 30 | G33: =IF(B33="Sa",SUM(G28:G32),IF(B33="So","",(E33-D33)*24-F33/60)) -> 8 | H33: /
B34: =TEXT(C34,"TTT") -> Di | C34: =C33+1 -> 45951 | D34: =IF(OR(B34="Sa",B34="So"), "", TIME(8,30,0)) -> 0.35416667 | E34: =IF(OR(B34="Sa",B34="So"), "", TIME(17,0,0)) -> 0.70833333 | F34: =IF(OR(B34="Sa",B34="So"), "", 30) -> 30 | G34: =IF(B34="Sa",SUM(G29:G33),IF(B34="So","",(E34-D34)*24-F34/60)) -> 8 | H34: /
B35: =TEXT(C35,"TTT") -> Mi | C35: =C34+1 -> 45952 | D35: =IF(OR(B35="Sa",B35="So"), "", TIME(8,30,0)) -> 0.35416667 | E35: =IF(OR(B35="Sa",B35="So"), "", TIME(17,0,0)) -> 0.70833333 | F35: =IF(OR(B35="Sa",B35="So"), "", 30) -> 30 | G35: =IF(B35="Sa",SUM(G30:G34),IF(B35="So","",(E35-D35)*24-F35/60)) -> 8 | H35: /
B36: =TEXT(C36,"TTT") -> Do | C36: =C35+1 -> 45953 | D36: =IF(OR(B36="Sa",B36="So"), "", TIME(8,30,0)) -> 0.35416667 | E36: =IF(OR(B36="Sa",B36="So"), "", TIME(17,0,0)) -> 0.70833333 | F36: =IF(OR(B36="Sa",B36="So"), "", 30) -> 30 | G36: =IF(B36="Sa",SUM(G31:G35),IF(B36="So","",(E36-D36)*24-F36/60)) -> 8 | H36: /
B37: =TEXT(C37,"TTT") -> Fr | C37: =C36+1 -> 45954 | D37: =IF(OR(B37="Sa",B37="So"), "", TIME(8,30,0)) -> 0.35416667 | E37: =IF(OR(B37="Sa",B37="So"), "", TIME(17,0,0)) -> 0.70833333 | F37: =IF(OR(B37="Sa",B37="So"), "", 30) -> 30 | G37: =IF(B37="Sa",SUM(G32:G36),IF(B37="So","",(E37-D37)*24-F37/60)) -> 8 | H37: /
B38: =TEXT(C38,"TTT") -> Sa | C38: =C37+1 -> 45955 | D38: =IF(OR(B38="Sa",B38="So"), "", TIME(8,30,0)) | E38: =IF(OR(B38="Sa",B38="So"), "", TIME(17,0,0)) | F38: =IF(OR(B38="Sa",B38="So"), "", 30) | G38: =IF(B38="Sa",SUM(G33:G37),IF(B38="So","",(E38-D38)*24-F38/60)) -> 40 | H38: /
B39: =TEXT(C39,"TTT") -> So | C39: =C38+1 -> 45956 | D39: =IF(OR(B39="Sa",B39="So"), "", TIME(8,30,0)) | E39: =IF(OR(B39="Sa",B39="So"), "", TIME(17,0,0)) | F39: =IF(OR(B39="Sa",B39="So"), "", 30) | G39: =IF(B39="Sa",SUM(G34:G38),IF(B39="So","",(E39-D39)*24-F39/60)) | H39: /
B40: =TEXT(C40,"TTT") -> Mo | C40: =C39+1 -> 45957 | D40: =IF(OR(B40="Sa",B40="So"), "", TIME(8,30,0)) -> 0.35416667 | E40: =IF(OR(B40="Sa",B40="So"), "", TIME(17,0,0)) -> 0.70833333 | F40: =IF(OR(B40="Sa",B40="So"), "", 30) -> 30 | G40: =IF(B40="Sa",SUM(G35:G39),IF(B40="So","",(E40-D40)*24-F40/60)) -> 8 | H40: /
B41: =TEXT(C41,"TTT") -> Di | C41: =C40+1 -> 45958 | D41: =IF(OR(B41="Sa",B41="So"), "", TIME(8,30,0)) -> 0.35416667 | E41: =IF(OR(B41="Sa",B41="So"), "", TIME(17,0,0)) -> 0.70833333 | F41: =IF(OR(B41="Sa",B41="So"), "", 30) -> 30 | G41: =IF(B41="Sa",SUM(G36:G40),IF(B41="So","",(E41-D41)*24-F41/60)) -> 8 | H41: /
B42: =TEXT(C42,"TTT") -> Mi | C42: =C41+1 -> 45959 | D42: =IF(OR(B42="Sa",B42="So"), "", TIME(8,30,0)) -> 0.35416667 | E42: =IF(OR(B42="Sa",B42="So"), "", TIME(17,0,0)) -> 0.70833333 | F42: =IF(OR(B42="Sa",B42="So"), "", 30) -> 30 | G42: =IF(B42="Sa",SUM(G37:G41),IF(B42="So","",(E42-D42)*24-F42/60)) -> 8 | H42: /
B43: =TEXT(C43,"TTT") -> Do | C43: =C42+1 -> 45960 | D43: =IF(OR(B43="Sa",B43="So"), "", TIME(8,30,0)) -> 0.35416667 | E43: =IF(OR(B43="Sa",B43="So"), "", TIME(17,0,0)) -> 0.70833333 | F43: =IF(OR(B43="Sa",B43="So"), "", 30) -> 30 | G43: =IF(B43="Sa",SUM(G38:G42),IF(B43="So","",(E43-D43)*24-F43/60)) -> 8 | H43: /
B44: =TEXT(C44,"TTT") -> Fr | C44: =C43+1 -> 45961 | D44: =IF(OR(B44="Sa",B44="So"), "", TIME(8,30,0)) -> 0.35416667 | E44: =IF(OR(B44="Sa",B44="So"), "", TIME(17,0,0)) -> 0.70833333 | F44: =IF(OR(B44="Sa",B44="So"), "", 30) -> 30 | G44: =IF(B44="Sa",SUM(G39:G43),IF(B44="So","",(E44-D44)*24-F44/60)) -> 8 | H44: /
B45: =TEXT(C45,"TTT") -> Sa | C45: =C44+1 -> 45962 | D45: =IF(OR(B45="Sa",B45="So"), "", TIME(8,30,0)) | E45: =IF(OR(B45="Sa",B45="So"), "", TIME(17,0,0)) | F45: =IF(OR(B45="Sa",B45="So"), "", 30) | G45: =IF(B45="Sa",SUM(G40:G44),IF(B45="So","",(E45-D45)*24-F45/60)) -> 40
...

Sheet November
B2: Praktikumsbetrieb
B3: Echoscout GmbH | F3: =Eingabedaten!B14 -> #VALUE!
B4: Maria-Goeppert-Str. 3
B5: 23562 Lübeck
B7: Stundennachweis
F8: Name, Vorname
B9: 45962 | F9: =Eingabedaten!C4 & ", " & Eingabedaten!C3 -> Sternicki, Michael
B13: Tag | C13: Datum | D13: Arbeitszeit von -bis | F13: Pause in min. | G13: Std. gesamt | H13: Bemerkung
B14: =TEXT(C14,"TTT") -> Sa | C14: =B9 -> 45962 | D14: =IF(OR(B14="Sa",B14="So"), "", TIME(8,30,0)) | E14: =IF(OR(B14="Sa",B14="So"), "", TIME(17,0,0)) | F14: =IF(OR(B14="Sa",B14="So"), "", 30) | G14: =IF(B14="Sa",SUM(G9:G13),IF(B14="So","",(E14-D14)*24-F14/60)) -> 0 | H14: /
B15: =TEXT(C15,"TTT") -> So | C15: =C14+1 -> 45963 | D15: =IF(OR(B15="Sa",B15="So"), "", TIME(8,30,0)) | E15: =IF(OR(B15="Sa",B15="So"), "", TIME(17,0,0)) | F15: =IF(OR(B15="Sa",B15="So"), "", 30) | G15: =IF(B15="Sa",SUM(G10:G14),IF(B15="So","",(E15-D15)*24-F15/60)) | H15: /
B16: =TEXT(C16,"TTT") -> Mo | C16: =C15+1 -> 45964 | D16: =IF(OR(B16="Sa",B16="So"), "", TIME(8,30,0)) -> 0.35416667 | E16: =IF(OR(B16="Sa",B16="So"), "", TIME(17,0,0)) -> 0.70833333 | F16: =IF(OR(B16="Sa",B16="So"), "", 30) -> 30 | G16: =IF(B16="Sa",SUM(G11:G15),IF(B16="So","",(E16-D16)*24-F16/60)) -> 8 | H16: /
B17: =TEXT(C17,"TTT") -> Di | C17: =C16+1 -> 45965 | D17: =IF(OR(B17="Sa",B17="So"), "", TIME(8,30,0)) -> 0.35416667 | E17: =IF(OR(B17="Sa",B17="So"), "", TIME(17,0,0)) -> 0.70833333 | F17: =IF(OR(B17="Sa",B17="So"), "", 30) -> 30 | G17: =IF(B17="Sa",SUM(G12:G16),IF(B17="So","",(E17-D17)*24-F17/60)) -> 8 | H17: /
B18: =TEXT(C18,"TTT") -> Mi | C18: =C17+1 -> 45966 | D18: =IF(OR(B18="Sa",B18="So"), "", TIME(8,30,0)) -> 0.35416667 | E18: =IF(OR(B18="Sa",B18="So"), "", TIME(17,0,0)) -> 0.70833333 | F18: =IF(OR(B18="Sa",B18="So"), "", 30) -> 30 | G18: =IF(B18="Sa",SUM(G13:G17),IF(B18="So","",(E18-D18)*24-F18/60)) -> 8 | H18: /
B19: =TEXT(C19,"TTT") -> Do | C19: =C18+1 -> 45967 | D19: =IF(OR(B19="Sa",B19="So"), "", TIME(8,30,0)) -> 0.35416667 | E19: =IF(OR(B19="Sa",B19="So"), "", TIME(17,0,0)) -> 0.70833333 | F19: =IF(OR(B19="Sa",B19="So"), "", 30) -> 30 | G19: =IF(B19="Sa",SUM(G14:G18),IF(B19="So","",(E19-D19)*24-F19/60)) -> 8 | H19: /
B20: =TEXT(C20,"TTT") -> Fr | C20: =C19+1 -> 45968 | D20: =IF(OR(B20="Sa",B20="So"), "", TIME(8,30,0)) -> 0.35416667 | E20: =IF(OR(B20="Sa",B20="So"), "", TIME(17,0,0)) -> 0.70833333 | F20: =IF(OR(B20="Sa",B20="So"), "", 30) -> 30 | G20: =IF(B20="Sa",SUM(G15:G19),IF(B20="So","",(E20-D20)*24-F20/60)) -> 8 | H20: /
B21: =TEXT(C21,"TTT") -> Sa | C21: =C20+1 -> 45969 | D21: =IF(OR(B21="Sa",B21="So"), "", TIME(8,30,0)) | E21: =IF(OR(B21="Sa",B21="So"), "", TIME(17,0,0)) | F21: =IF(OR(B21="Sa",B21="So"), "", 30) | G21: =IF(B21="Sa",SUM(G16:G20),IF(B21="So","",(E21-D21)*24-F21/60)) -> 40 | H21: /
B22: =TEXT(C22,"TTT") -> So | C22: =C21+1 -> 45970 | D22: =IF(OR(B22="Sa",B22="So"), "", TIME(8,30,0)) | E22: =IF(OR(B22="Sa",B22="So"), "", TIME(17,0,0)) | F22: =IF(OR(B22="Sa",B22="So"), "", 30) | G22: =IF(B22="Sa",SUM(G17:G21),IF(B22="So","",(E22-D22)*24-F22/60)) | H22: /
B23: =TEXT(C23,"TTT") -> Mo | C23: =C22+1 -> 45971 | D23: =IF(OR(B23="Sa",B23="So"), "", TIME(8,30,0)) -> 0.35416667 | E23: =IF(OR(B23="Sa",B23="So"), "", TIME(17,0,0)) -> 0.70833333 | F23: =IF(OR(B23="Sa",B23="So"), "", 30) -> 30 | G23: =IF(B23="Sa",SUM(G18:G22),IF(B23="So","",(E23-D23)*24-F23/60)) -> 8 | H23: /
B24: =TEXT(C24,"TTT") -> Di | C24: =C23+1 -> 45972 | D24: =IF(OR(B24="Sa",B24="So"), "", TIME(8,30,0)) -> 0.35416667 | E24: =IF(OR(B24="Sa",B24="So"), "", TIME(17,0,0)) -> 0.70833333 | F24: =IF(OR(B24="Sa",B24="So"), "", 30) -> 30 | G24: =IF(B24="Sa",SUM(G19:G23),IF(B24="So","",(E24-D24)*24-F24/60)) -> 8 | H24: /
B25: =TEXT(C25,"TTT") -> Mi | C25: =C24+1 -> 45973 | D25: =IF(OR(B25="Sa",B25="So"), "", TIME(8,30,0)) -> 0.35416667 | E25: =IF(OR(B25="Sa",B25="So"), "", TIME(17,0,0)) -> 0.70833333 | F25: =IF(OR(B25="Sa",B25="So"), "", 30) -> 30 | G25: =IF(B25="Sa",SUM(G20:G24),IF(B25="So","",(E25-D25)*24-F25/60)) -> 8 | H25: /
B26: =TEXT(C26,"TTT") -> Do | C26: =C25+1 -> 45974 | D26: =IF(OR(B26="Sa",B26="So"), "", TIME(8,30,0)) -> 0.35416667 | E26: =IF(OR(B26="Sa",B26="So"), "", TIME(17,0,0)) -> 0.70833333 | F26: =IF(OR(B26="Sa",B26="So"), "", 30) -> 30 | G26: =IF(B26="Sa",SUM(G21:G25),IF(B26="So","",(E26-D26)*24-F26/60)) -> 8 | H26: /
... B44: =TEXT(C44,"TTT") -> Mo | C44: =C43+1 -> 45992 | D44: =IF(OR(B44="Sa",B44="So"), "", TIME(8,30,0)) -> 0.35416667 | E44: =IF(OR(B44="Sa",B44="So"), "", TIME(17,0,0)) -> 0.70833333 | F44: =IF(OR(B44="Sa",B44="So"), "", 30) -> 30 | G44: =IF(B44="Sa",SUM(G39:G43),IF(B44="So","",(E44-D44)*24-F44/60)) -> 8 | H44: /
B45: =TEXT(C45,"TTT") -> Di | C45: =C44+1 -> 45993 | D45: =IF(OR(B45="Sa",B45="So"), "", TIME(8,30,0)) -> 0.35416667 | E45: =IF(OR(B45="Sa",B45="So"), "", TIME(17,0,0)) -> 0.70833333 | F45: =IF(OR(B45="Sa",B45="So"), "", 30) -> 30 | G45: =IF(B45="Sa",SUM(G40:G44),IF(B45="So","",(E45-D45)*24-F45/60)) -> 8
B47: =Eingabedaten!B18 -> #VALUE!
F48: =Eingabedaten!B22 -> 0
B50: =C44 -> 45992 | F50: =B50 -> 45992
B51: Datum, Unterschrift Teilnehmer | F51: Datum, Stempel, Unterschrift Betrieb

Sheet Dezember
B2: Praktikumsbetrieb
B3: Echoscout GmbH | F3: =Eingabedaten!B14 -> #VALUE!
B4: Maria-Goeppert-Str. 3
B5: 23562 Lübeck
B7: Stundennachweis
F8: Name, Vorname
B9: 45992 | F9: =Eingabedaten!C4 & ", " & Eingabedaten!C3 -> Sternicki, Michael
B13: Tag | C13: Datum | D13: Arbeitszeit von -bis | F13: Pause in min. | G13: Std. gesamt | H13: Bemerkung
B14: =TEXT(C14,"TTT") -> Mo | C14: =B9 -> 45992 | D14: =IF(OR(B14="Sa",B14="So"), "", TIME(8,30,0)) -> 0.35416667 | E14: =IF(OR(B14="Sa",B14="So"), "", TIME(17,0,0)) -> 0.70833333 | F14: =IF(OR(B14="Sa",B14="So"), "", 30) -> 30 | G14: =IF(B14="Sa",SUM(G9:G13),IF(B14="So","",(E14-D14)*24-F14/60)) -> 8 | H14: /
B15: =TEXT(C15,"TTT") -> Di | C15: =C14+1 -> 45993 | D15: =IF(OR(B15="Sa",B15="So"), "", TIME(8,30,0)) -> 0.35416667 | E15: =IF(OR(B15="Sa",B15="So"), "", TIME(17,0,0)) -> 0.70833333 | F15: =IF(OR(B15="Sa",B15="So"), "", 30) -> 30 | G15: =IF(B15="Sa",SUM(G10:G14),IF(B15="So","",(E15-D15)*24-F15/60)) -> 8 | H15: /
B16: =TEXT(C16,"TTT") -> Mi | C16: =C15+1 -> 45994 | D16: =IF(OR(B16="Sa",B16="So"), "", TIME(8,30,0)) -> 0.35416667 | E16: =IF(OR(B16="Sa",B16="So"), "", TIME(17,0,0)) -> 0.70833333 | F16: =IF(OR(B16="Sa",B16="So"), "", 30) -> 30 | G16: =IF(B16="Sa",SUM(G11:G15),IF(B16="So","",(E16-D16)*24-F16/60)) -> 8 | H16: /
B17: =TEXT(C17,"TTT") -> Do | C17: =C16+1 -> 45995 | D17: =IF(OR(B17="Sa",B17="So"), "", TIME(8,30,0)) -> 0.35416667 | E17: =IF(OR(B17="Sa",B17="So"), "", TIME(17,0,0)) -> 0.70833333 | F17: =IF(OR(B17="Sa",B17="So"), "", 30) -> 30 | G17: =IF(B17="Sa",SUM(G12:G16),IF(B17="So","",(E17-D17)*24-F17/60)) -> 8 | H17: /
B18: =TEXT(C18,"TTT") -> Fr | C18: =C17+1 -> 45996 | D18: =IF(OR(B18="Sa",B18="So"), "", TIME(8,30,0)) -> 0.35416667 | E18: =IF(OR(B18="Sa",B18="So"), "", TIME(17,0,0)) -> 0.70833333 | F18: =IF(OR(B18="Sa",B18="So"), "", 30) -> 30 | G18: =IF(B18="Sa",SUM(G13:G17),IF(B18="So","",(E18-D18)*24-F18/60)) -> 8 | H18: /
B19: =TEXT(C19,"TTT") -> Sa | C19: =C18+1 -> 45997 | D19: =IF(OR(B19="Sa",B19="So"), "", TIME(8,30,0)) | E19: =IF(OR(B19="Sa",B19="So"), "", TIME(17,0,0)) | F19: =IF(OR(B19="Sa",B19="So"), "", 30) | G19: =IF(B19="Sa",SUM(G14:G18),IF(B19="So","",(E19-D19)*24-F19/60)) -> 40 | H19: /
B20: =TEXT(C20,"TTT") -> So | C20: =C19+1 -> 45998 | D20: =IF(OR(B20="Sa",B20="So"), "", TIME(8,30,0)) | E20: =IF(OR(B20="Sa",B20="So"), "", TIME(17,0,0)) | F20: =IF(OR(B20="Sa",B20="So"), "", 30) | G20: =IF(B20="Sa",SUM(G15:G19),IF(B20="So","",(E20-D20)*24-F20/60)) | H20: /
B21: =TEXT(C21,"TTT") -> Mo | C21: =C20+1 -> 45999 | D21: =IF(OR(B21="Sa",B21="So"), "", TIME(8,30,0)) -> 0.35416667 | E21: =IF(OR(B21="Sa",B21="So"), "", TIME(17,0,0)) -> 0.70833333 | F21: =IF(OR(B21="Sa",B21="So"), "", 30) -> 30 | G21: =IF(B21="Sa",SUM(G16:G20),IF(B21="So","",(E21-D21)*24-F21/60)) -> 8 | H21: /
B22: =TEXT(C22,"TTT") -> Di | C22: =C21+1 -> 46000 | D22: =IF(OR(B22="Sa",B22="So"), "", TIME(8,30,0)) -> 0.35416667 | E22: =IF(OR(B22="Sa",B22="So"), "", TIME(17,0,0)) -> 0.70833333 | F22: =IF(OR(B22="Sa",B22="So"), "", 30) -> 30 | G22: =IF(B22="Sa",SUM(G17:G21),IF(B22="So","",(E22-D22)*24-F22/60)) -> 8 | H22: /
B23: =TEXT(C23,"TTT") -> Mi | C23: =C22+1 -> 46001 | D23: =IF(OR(B23="Sa",B23="So"), "", TIME(8,30,0)) -> 0.35416667 | E23: =IF(OR(B23="Sa",B23="So"), "", TIME(17,0,0)) -> 0.70833333 | F23: =IF(OR(B23="Sa",B23="So"), "", 30) -> 30 | G23: =IF(B23="Sa",SUM(G18:G22),IF(B23="So","",(E23-D23)*24-F23/60)) -> 8 | H23: /
B24: =TEXT(C24,"TTT") -> Do | C24: =C23+1 -> 46002 | D24: =IF(OR(B24="Sa",B24="So"), "", TIME(8,30,0)) -> 0.35416667 | E24: =IF(OR(B24="Sa",B24="So"), "", TIME(17,0,0)) -> 0.70833333 | F24: =IF(OR(B24="Sa",B24="So"), "", 30) -> 30 | G24: =IF(B24="Sa",SUM(G19:G23),IF(B24="So","",(E24-D24)*24-F24/60)) -> 8 | H24: /
B25: =TEXT(C25,"TTT") -> Fr | C25: =C24+1 -> 46003 | D25: =IF(OR(B25="Sa",B25="So"), "", TIME(8,30,0)) -> 0.35416667 | E25: =IF(OR(B25="Sa",B25="So"), "", TIME(17,0,0)) -> 0.70833333 | F25: =IF(OR(B25="Sa",B25="So"), "", 30) -> 30 | G25: =IF(B25="Sa",SUM(G20:G24),IF(B25="So","",(E25-D25)*24-F25/60)) -> 8 | H25: /
B26: =TEXT(C26,"TTT") -> Sa | C26: =C25+1 -> 46004 | D26: =IF(OR(B26="Sa",B26="So"), "", TIME(8,30,0)) | E26: =IF(OR(B26="Sa",B26="So"), "", TIME(17,0,0)) | F26: =IF(OR(B26="Sa",B26="So"), "", 30) | G26: =IF(B26="Sa",SUM(G21:G25),IF(B26="So","",(E26-D26)*24-F26/60)) -> 40 | H26: /
... B44: =TEXT(C44,"TTT") -> Mi | C44: =C43+1 -> 46022 | D44: =IF(OR(B44="Sa",B44="So"), "", TIME(8,30,0)) -> 0.35416667 | E44: =IF(OR(B44="Sa",B44="So"), "", TIME(17,0,0)) -> 0.70833333 | F44: =IF(OR(B44="Sa",B44="So"), "", 30) -> 30 | G44: =IF(B44="Sa",SUM(G39:G43),IF(B44="So","",(E44-D44)*24-F44/60)) -> 8 | H44: /
B45: =TEXT(C45,"TTT") -> Do | C45: =C44+1 -> 46023 | D45: =IF(OR(B45="Sa",B45="So"), "", TIME(8,30,0)) -> 0.35416667 | E45: =IF(OR(B45="Sa",B45="So"), "", TIME(17,0,0)) -> 0.70833333 | F45: =IF(OR(B45="Sa",B45="So"), "", 30) -> 30 | G45: =IF(B45="Sa",SUM(G40:G44),IF(B45="So","",(E45-D45)*24-F45/60)) -> 8
B47: =Eingabedaten!B18 -> #VALUE!
F48: =Eingabedaten!B22 -> 0
B50: =C44 -> 46022 | F50: =B50 -> 46022
B51: Datum, Unterschrift Teilnehmer | F51: Datum, Stempel, Unterschrift Betrieb

Sheet PRINT KW40
B3: Praktikumsbetrieb
B4: Echoscout GmbH | F4: =Eingabedaten!B14 -> #VALUE!
B5: Maria-Goeppert-Str. 3
B6: 23562 Lübeck
B8: Stundennachweis | F8: =Eingabedaten!C4 & ", " & Eingabedaten!C3 -> Sternicki, Michael
F9: Name, Vorname
B11: KW | C11: 40
B12: Tag | C12: Datum | D12: Arbeitszeit von -bis | F12: Pause in min. | G12: Std. gesamt | H12: Bemerkung
B13: Mo | C13: =DATE(Eingabedaten!C5,1,1) + (C11-1)*7 + 1 - WEEKDAY(DATE(Eingabedaten!C5,1,1)-1) -> 45929 | D13: 0.35416667 | E13: 0.70833333 | F13: 30 | G13: =(E13-D13)*24-F13/60 -> 8 | H13: /
B14: Di | C14: =C13+1 -> 45930 | D14: =D13 -> 0.35416667 | E14: =E13 -> 0.70833333 | F14: =F13 -> 30 | G14: =(E14-D14)*24-F14/60 -> 8 | H14: /
B15: Mi | C15: =C14+1 -> 45931 | D15: =D14 -> 0.35416667 | E15: =E14 -> 0.70833333 | F15: =F14 -> 30 | G15: =(E15-D15)*24-F15/60 -> 8 | H15: /
B16: Do | C16: =C15+1 -> 45932 | D16: =D15 -> 0.35416667 | E16: =E15 -> 0.70833333 | F16: =F15 -> 30 | G16: =(E16-D16)*24-F16/60 -> 8 | H16: /
B17: Fr | C17: =C16+1 -> 45933 | D17: =D16 -> 0.35416667 | E17: =E16 -> 0.70833333 | F17: =F16 -> 30 | G17: =(E17-D17)*24-F17/60 -> 8 | H17: /
B18: Sa | C18: =C17+1 -> 45934 | D18: / | E18: / | F18: / | G18: / | H18: /
G19: =SUM(G13:G18) -> 40
B20: =Eingabedaten!B18 -> #VALUE!
F21: =Eingabedaten!B22 -> 0
B23: =C17 -> 45933 | F23: =C17 -> 45933
B24: Datum, Unterschrift Teilnehmer | F24: Datum, Stempel, Unterschrift Betrieb
B26: Praktikumsbetrieb
B27: =B4 -> Echoscout GmbH | F27: =F4 -> #VALUE!
B28: =B5 -> Maria-Goeppert-Str. 3
B29: =B6 -> 23562 Lübeck
B31: Stundennachweis | F31: =F8 -> Sternicki, Michael
F32: Name, Vorname
B34: KW | C34: =C11+1 -> 41
B35: Tag | C35: Datum | D35: Arbeitszeit von -bis | F35: Pause in min. | G35: Std. gesamt | H35: Bemerkung
B36: Mo | C36: =DATE(Eingabedaten!C5,1,1) + (C34-1)*7 + 1 - WEEKDAY(DATE(Eingabedaten!C5,1,1)-1) -> 45936 | D36: 0.35416667 | E36: 0.70833333 | F36: 30 | G36: =(E36-D36)*24-F36/60 -> 8 | H36: /
B37: Di | C37: =C36+1 -> 45937 | D37: =D36 -> 0.35416667 | E37: =E36 -> 0.70833333 | F37: =F36 -> 30 | G37: =(E37-D37)*24-F37/60 -> 8 | H37: /
B38: Mi | C38: =C37+1 -> 45938 | D38: =D37 -> 0.35416667 | E38: =E37 -> 0.70833333 | F38: =F37 -> 30 | G38: =(E38-D38)*24-F38/60 -> 8 | H38: /
B39: Do | C39: =C38+1 -> 45939 | D39: =D38 -> 0.35416667 | E39: =E38 -> 0.70833333 | F39: =F38 -> 30 | G39: =(E39-D39)*24-F39/60 -> 8 | H39: /
B40: Fr | C40: =C39+1 -> 45940 | D40: =D39 -> 0.35416667 | E40: =E39 -> 0.70833333 | F40: =F39 -> 30 | G40: =(E40-D40)*24-F40/60 -> 8 | H40: /
B41: Sa | C41: =C40+1 -> 45941 | D41: / | E41: / | F41: / | G41: / | H41: /
G42: =SUM(G36:G40) -> 40
B43: =Eingabedaten!B18 -> #VALUE!
F44: =Eingabedaten!B22 -> 0
B46: =C40 -> 45940 | F46: =C40 -> 45940
B47: Datum, Unterschrift Teilnehmer | F47: Datum, Stempel, Unterschrift Betrieb
